Workbook

Sheet Luxury Proposal (17 Sections)
A2: LUXURY INTERIOR DESIGN & TURNKEY FITOUT QUOTATION
A3: DECOR8 INDIA | D3: DECOR8 INDIA
A4: #14, Sy NO 36/1 Vasanth Vallabhnagar, Vasanthapura
A5: Uttarahalli Hobli, Bengaluru - 560061 | D5: Affordable Luxury Interiors www.decor8india.com
A6: +91 88841 31414 , +91 93805 23743
A7: GSTIN: 29CHPPB0944C2ZD
A9: QUOTATION FOR — MR. GOVINDA (Kolte Patil D1304) | D9: Representative: Mr. Satish Bhat (CEO)
A10: Quotation No: | B10: D8202607102 | D10: Quotation Date: | F10: 06-AUG-2026
A11: Contact No: | B11: +91 93805 23743 / +91 88841 31414 | D11: Project Location: | F11: Kolte Patil D1304, Bengaluru
A12: Project Type: | B12: Complete 3BHK Turnkey Interior | D12: Quotation Status: | F12: Official Luxury Proposal
A14: PROJECT SCOPE & CATEGORY DIRECTORY
A15: # | B15: Scope Category / Room | C15: Key Materials & Design Scope | E15: Section Sub-Total (₹)
A16: 01 | B16: Modular Kitchen & Sink | C16: AICA Acrylic + CenturyPly 710 BWP + Carysil Sink | E16: =F50+F61 -> 547600
A17: 02 | B17: Living Room | C17: Vitrified Marble Wall + Fluted Rafters + 5-Seater Sofa | E17: =F96 -> 377550
A18: 03 | B18: Dining Area | C18: 6-Seater Marble Dining Table & Upholstered Chairs | E18: =F121 -> 142700
A19: 04 | B19: Master Bedroom | C19: Lacquered Glass Wardrobe + Queen Hydraulic Bed | E19: =F155 -> 381600
A20: 05 | B20: Bedroom 02 | C20: High Gloss Acrylic Wardrobe + King Hydraulic Bed | E20: =F184 -> 313988
A21: 06 | B21: Bedroom 03 | C21: High Gloss Acrylic Wardrobe + King Hydraulic Bed | E21: =F211 -> 313900
A22: 07-09 | B22: Maid, Vanity & Utility | C22: Carcass 710 BWP + KalingaStone + Jaquar + Storage | E22: =F219+F232+F240 -> 145975
A23: 10-11 | B23: False Ceiling & Electrical | C23: Gyproc False Ceiling + Havells LED + Chandelier | E23: =F250+F266 -> 390120
A24: 12-14 | B24: Plumbing, Painting & Cleaning | C24: Asian Paints Royale + Jaquar Plumbing + Deep Clean | E24: =F274+F282+F290 -> 188700
A25: 15-17 | B25: Design, Logistics & Management | C25: 2D/3D Architecture + Site Oversight + Transport | E25: =F303+F311+F324 -> 120000
A26: TOTAL ESTIMATED TURNKEY VALUE (INCL. 18% GST) | E26: =E352 -> 3448117
A27: * Please turn to individual pages ahead for full-scale visual elevations, itemized material specifications, and milestone schedules.
A28: SECTION 01 OF 17
A29: Modular Kitchen | E29: =F50+F61 -> 547600
A30: AICA High Gloss Acrylic • CenturyPly • Hettich
D32: Kitchen Finish (Reference Image)
D33: — AICA High Gloss Acrylic Shutters
D34: — CenturyPly 710 BWP — Base Units
D35: — CenturyPly 310 MR — Wall & Loft
D36: — Hettich Hinges & Tandem Channels
D37: — LED Under-Cabinet Lighting
D38: — Factory Manufactured • CNC Cut
A44: Item | B44: Specification & Materials | C44: Qty | D44: Unit | E44: Rate (₹) | F44: Amount (₹)
A45: Base Units | B45: 72 Sq.ft × ₹2,300 — CenturyPly 710 BWP, Acrylic | C45: 72 | D45: Sq.ft | E45: 2300 | F45: =C45*E45 -> 165600
A46: Wall Units | B46: 48 Sq.ft × ₹2,150 — CenturyPly 310 MR, Acrylic | C46: 48 | D46: Sq.ft | E46: 2150 | F46: =C46*E46 -> 103200
A47: Loft | B47: 48 Sq.ft × ₹1,450 — CenturyPly 310 MR, Laminate | C47: 48 | D47: Sq.ft | E47: 1450 | F47: =C47*E47 -> 69600
A48: Kitchen Accessories | B48: Hettich Cutlery + Pots & Pan + Baskets + Oil Pull-Out + Wicker | C48: 1 | D48: Set | E48: 42000 | F48: =C48*E48 -> 42000
A49: Quartz Countertop | B49: 54 Sq.ft × ₹2,200 — KalingaStone Premium | C49: 54 | D49: Sq.ft | E49: 2200 | F49: =C49*E49 -> 118800
...

Sheet Executive Grand Summary
A2: DECOR8 INDIA — EXECUTIVE COST BREAKDOWN & PROJECT SUMMARY
A3: Client: MR. GOVINDA | Project: Kolte Patil D1304 | D3: Quotation No: D8202607102 | Date: 06-AUG-2026
A5: # | B5: Section / Room Description | C5: Scope Type | D5: % Total | E5: Amount (₹) | F5: Specifications Highlights
A6: 01 | B6: Modular Kitchen (Units) | C6: Joinery & Woodwork | D6: =E6/$E$24 -> 0.17083411 | E6: ='Luxury Proposal (17 Sections)'!F50 -> 499200 | F6: Acrylic + Century BWP 710 + Hettich
B7: Kitchen Sink & Plumbing Materials | C7: Sanitary & Fixtures | D7: =E7/$E$24 -> 0.016563243 | E7: ='Luxury Proposal (17 Sections)'!F61 -> 48400 | F7: Carysil Quartz Sink + Jaquar Mixer
A8: 02 | B8: Living Room | C8: Furniture & Panelling | D8: =E8/$E$24 -> 0.12920356 | E8: ='Luxury Proposal (17 Sections)'!F96 -> 377550 | F8: Vitrified Wall + Rafters + 5-Seater Sofa
A9: 03 | B9: Dining Area | C9: Loose Furniture | D9: =E9/$E$24 -> 0.048834191 | E9: ='Luxury Proposal (17 Sections)'!F121 -> 142700 | F9: 6-Seater Marble Dining Table & Chairs
A10: 04 | B10: Master Bedroom | C10: Joinery & Furniture | D10: =E10/$E$24 -> 0.13058954 | E10: ='Luxury Proposal (17 Sections)'!F155 -> 381600 | F10: Lacquered Glass Wardrobe + Queen Bed
A11: 05 | B11: Bedroom 02 | C11: Joinery & Furniture | D11: =E11/$E$24 -> 0.10745165 | E11: ='Luxury Proposal (17 Sections)'!F184 -> 313988 | F11: Acrylic Sliding Wardrobe + King Bed
A12: 06 | B12: Bedroom 03 | C12: Joinery & Furniture | D12: =E12/$E$24 -> 0.10742153 | E12: ='Luxury Proposal (17 Sections)'!F211 -> 313900 | F12: Acrylic Sliding Wardrobe + King Bed
A13: 07 | B13: Maid Room | C13: Joinery & Furniture | D13: =E13/$E$24 -> 0.010446136 | E13: ='Luxury Proposal (17 Sections)'!F219 -> 30525 | F13: Single Bed with Hydraulic Storage
A14: 08 | B14: Bathroom Vanity Units | C14: Sanitary & Joinery | D14: =E14/$E$24 -> 0.022825792 | E14: ='Luxury Proposal (17 Sections)'!F232 -> 66700 | F14: Marine Carcass + KalingaStone Top + Jaquar
A15: 09 | B15: Utility Storage | C15: Joinery & Woodwork | D15: =E15/$E$24 -> 0.016683019 | E15: ='Luxury Proposal (17 Sections)'!F240 -> 48750 | F15: Base + Wall + Loft Century 710 BWP
A16: 10 | B16: False Ceiling | C16: Civil & Ceiling | D16: =E16/$E$24 -> 0.089044544 | E16: ='Luxury Proposal (17 Sections)'!F250 -> 260200 | F16: Saint-Gobain Gyproc + PVC + Grid
A17: 11 | B17: Electrical & Lighting | C17: Electrical | D17: =E17/$E$24 -> 0.044460673 | E17: ='Luxury Proposal (17 Sections)'!F266 -> 129920 | F17: Havells LED + Chandelier + Profile Lights
A18: 12 | B18: Plumbing Labour | C18: Plumbing | D18: =E18/$E$24 -> 0.0041065893 | E18: ='Luxury Proposal (17 Sections)'!F274 -> 12000 | F18: Sanitary, Sink & Pressure Testing
A19: 13 | B19: Painting | C19: Finishing | D19: =E19/$E$24 -> 0.05533629 | E19: ='Luxury Proposal (17 Sections)'!F282 -> 161700 | F19: Asian Paints Royale Luxury (3,850 Sq.ft)
A20: 14 | B20: Deep Cleaning | C20: Logistics & Handover | D20: =E20/$E$24 -> 0.0051332366 | E20: ='Luxury Proposal (17 Sections)'!F290 -> 15000 | F20: Professional Deep Cleaning & Sanitization
A21: 15 | B21: Design Fees | C21: Architecture & Design | D21: =E21/$E$24 -> 0.022586241 | E21: ='Luxury Proposal (17 Sections)'!F303 -> 66000 | F21: 2D/3D Drawings & Walkthrough Video
A22: 16 | B22: Loading & Unloading | C22: Logistics | D22: =E22/$E$24 -> 0.0041065893 | E22: ='Luxury Proposal (17 Sections)'!F311 -> 12000 | F22: Material Transport & Vertical Shifting
A23: 17 | B23: Project Management | C23: Supervision & Execution | D23: =E23/$E$24 -> 0.014373062 | E23: ='Luxury Proposal (17 Sections)'!F324 -> 42000 | F23: Full Tenure Site Oversight & Snagging
A24: GRAND TOTAL (EXCL. GST) | D24: =SUM(D6:D23) -> 1 | E24: =SUM(E6:E23) -> 2922133 | F24: Base Project Value
A25: CGST @ 9% | E25: =ROUND(E24*0.09, 0) -> 262992 | F25: Central GST (9%)
A26: SGST @ 9% | E26: =ROUND(E24*0.09, 0) -> 262992 | F26: State GST (9%)
A27: FINAL ESTIMATED PROJECT VALUE (INCL. 18% GST) | E27: =E24+E25+E26 -> 3448117 | F27: Complete Turnkey Cost
A29: Payment Milestones: 15% Booking Confirmation | 50% Factory Production | 35% Pre-Dispatch to Site

Sheet Govinda D1304 (BOQ Format)
A2: DECOR8 INDIA — BILL OF QUANTITIES (BOQ)
A3: QUOTATION FOR — MR. GOVINDA - Kolte Patil D1304 | D3: Representative: Mr. Satish Bhat
A5: Section A: Wood work & Modular Finish CENTURY PLY
A6: Item Name | B6: Sub Item Name / Description | C6: Total SQFT | D6: Unit | E6: Rate | F6: Amount
A7: Utility storage | B7: Profile shutters — For TV unit and kitchen | C7: 26 | D7: Sq.ft | E7: 1100 | F7: =C7*E7 -> 28600
A8: Loft | B8: Loft — Frame with shutters | C8: 38 | D8: Sq.ft | E8: 950 | F8: =C8*E8 -> 36100
A9: Tall Unit | B9: Tall Storage Unit | C9: 18 | D9: Sq.ft | E9: 1550 | F9: =C9*E9 -> 27900
A10: Wicker Basket | B10: Wicker Basket — 2 Baskets | C10: 1 | D10: Set | E10: 12000 | F10: =C10*E10 -> 12000
A11: KBR Wardrobe | B11: Swing Wardrobe — Century MR Ply carcase & Laminate Finish | C11: 60 | D11: Sq.ft | E11: 1550 | F11: =C11*E11 -> 93000
A12: KBR Loft | B12: Loft — Frame with shutters | C12: 36 | D12: Sq.ft | E12: 950 | F12: =C12*E12 -> 34200
A13: Sub Total excluding GST (A) | F13: =SUM(F7:F12) -> 231800
A15: Section B: Appliances & Accessories
A16: Item Name | B16: Sub Item Name / Description | C16: Total SQFT | D16: Unit | E16: Rate | F16: Amount
A17: Kitchen Hardware | B17: Hob and Chimney (Elica / Kutchina) | C17: 1 | D17: Set | E17: 0 | F17: =C17*E17 -> 0
A18: Kitchen Hardware | B18: Sink | C18: 1 | D18: No. | E18: 0 | F18: =C18*E18 -> 0
A19: Kitchen Hardware | B19: Inbuilt Oven and Microwave (Model selection price may vary) | C19: 1 | D19: Set | E19: 0 | F19: =C19*E19 -> 0
A20: Kitchen Hardware | B20: Copper pipe for Gas Cylinder connection | C20: 1 | D20: L.S. | E20: 0 | F20: =C20*E20 -> 0
A21: Kitchen Hardware | B21: 1x cutlery with tandem drawer | C21: 1 | D21: No. | E21: 0 | F21: =C21*E21 -> 0
A22: Kitchen Hardware | B22: 1x plain ss basket drawer | C22: 1 | D22: No. | E22: 0 | F22: =C22*E22 -> 0
A23: Kitchen Hardware | B23: Rolling shutter | C23: 1 | D23: No. | E23: 0 | F23: =C23*E23 -> 0
A24: Kitchen Hardware | B24: 1x thali basket, Magic corner, Wicker basket | C24: 1 | D24: Set | E24: 0 | F24: =C24*E24 -> 0
A25: Wardrobes Hardware | B25: Handles, hinges and required hardwares added | C25: 1 | D25: Set | E25: 23500 | F25: =C25*E25 -> 23500
A26: Sub Total excluding GST (B) | F26: =SUM(F17:F25) -> 23500
A28: Section C: Miscellaneous & Loose Furniture
A29: Item Name | B29: Sub Item Name / Description | C29: Total SQFT | D29: Unit | E29: Rate | F29: Amount
A30: King size bed | B30: King size bed Hydraulic with Headboard and side table | C30: 1 | D30: Unit | E30: 0 | F30: =C30*E30 -> 0
A31: Queen size bed | B31: Queen size bed Hydraulic with Headboard and side table with cushion | C31: 1 | D31: Unit | E31: 0 | F31: =C31*E31 -> 0
A32: Wallpapers | B32: Premium textured designer wallpapers as per selection | C32: 1 | D32: L.S. | E32: 0 | F32: =C32*E32 -> 0
A33: Painting | B33: Royale Aspira — 1 coat primer + 2 coats Asian Paints Aspira | C33: 1 | D33: L.S. | E33: 0 | F33: =C33*E33 -> 0
A34: Quartz/Granite stone | B34: Countertop stone including cutting, edge moulding & installation | C34: 1 | D34: L.S. | E34: 0 | F34: =C34*E34 -> 0
A35: Electrical work | B35: Wiring, pop wiring, switches, modular plates etc. | C35: 1 | D35: L.S. | E35: 0 | F35: =C35*E35 -> 0
A36: Sub Total excluding GST (C) | F36: =SUM(F30:F35) -> 0
A38: Total Project Cost (A+B+C) excluding GST | F38: =F13+F26+F36 -> 255300
A39: CGST @ 9% | F39: =ROUND(F38*0.09, 0) -> 22977
A40: SGST @ 9% | F40: =ROUND(F38*0.09, 0) -> 22977
A41: Total Project Cost (A+B+C) including GST | F41: =F38+F39+F40 -> 301254
